/*
 How to avoid using try/catch blocks with promises' that could fail using async/await
 - https://blog.grossman.io/how-to-write-async-await-without-try-catch-blocks-in-javascript/
 */
const assertRejects = async (q, msg) => {
  let res, catchFlag = false
  try {
    res = await q
    // checks if there was a Log event and its argument l contains string "R<number>"
    catchFlag = res.logs && !!res.logs.find(log => log.event === "Log" && /\bR(\d+\.?)+/.test(log.args.l))
  } catch (e) {
    catchFlag = true
  } finally {
    if (!catchFlag) {
      assert.fail(res, null, msg)
    }
  }
}

module.exports = {
  assertRejects,
}